<?xml version="1.0" encoding="utf-8"?>
<!-- This URDF was automatically created by SolidWorks to URDF Exporter! Originally created by Stephen Brawner (brawner@gmail.com) 
     Commit Version: 1.6.0-4-g7f85cfe  Build Version: 1.6.7995.38578
     For more information, please see http://wiki.ros.org/sw_urdf_exporter -->
<robot
  name="car2">
  <link
    name="base_link">
    <inertial>
      <origin
        xyz="0.0038977 -8.1315E-19 0.021661"
        rpy="0 0 0" />
      <mass
        value="10.1" />
      <inertia
        ixx="0.061539"
        ixy="0.0"
        ixz="0.0018957"
        iyy="0.058968"
        iyz="0.0"
        izz="0.112703" />
    </inertial>
    <visual>
      <origin
        xyz="0 0 0"
        rpy="0 0 0" />
      <geometry>
        <mesh
          filename="package://car2/meshes/base_link.STL" />
      </geometry>
      <material
        name="">
        <color
          rgba="0.77647 0.75686 0.73725 1" />
      </material>
    </visual>
    <collision>
      <origin
        xyz="0 0 0"
        rpy="0 0 0" />
      <geometry>
        <mesh
          filename="package://car2/meshes/base_link.STL" />
      </geometry>
    </collision>
  </link>
  <link
    name="castwheel">
    <inertial>
      <origin
        xyz="-0.034033 0.0046637 -0.047711"
        rpy="0 0 0" />
      <mass
        value="1.957" />
      <inertia
        ixx="0.0012525"
        ixy="0.0"
        ixz="0.0"
        iyy="0.0012525"
        iyz="0.0"
        izz="0.0012525" />
    </inertial>
    <visual>
      <origin
        xyz="0 0 0"
        rpy="0 0 0" />
      <geometry>
        <mesh
          filename="package://car2/meshes/castwheel.STL" />
      </geometry>
      <material
        name="">
        <color
          rgba="0.64706 0.61961 0.58824 1" />
      </material>
    </visual>
    <collision>
      <origin
        xyz="0 0 0"
        rpy="0 0 0" />
      <geometry>
        <mesh
          filename="package://car2/meshes/castwheel.STL" />
      </geometry>
    </collision>
  </link>
  <joint
    name="castwheel_joint"
    type="continuous">
    <origin
      xyz="-0.0164468565720474 -0.00527324448375706 -0.025"
      rpy="1.79986954685685 -0.424347021577185 0.792685410767129" />
    <parent
      link="base_link" />
    <child
      link="castwheel" />
    <axis
      xyz="0.578881459990206 -0.0793276054052651 0.811543828945962" />
  </joint>
  <link
    name="leftwheel">
    <inertial>
      <origin
        xyz="2.3592E-16 4.1633E-17 0.0098391"
        rpy="0 0 0" />
      <mass
        value="0.3096" />
      <inertia
        ixx="9.7396E-05"
        ixy="0.0"
        ixz="0.0"
        iyy="9.7396E-05"
        iyz="0.0"
        izz="0.00017415" />
    </inertial>
    <visual>
      <origin
        xyz="0 0 0"
        rpy="0 0 0" />
      <geometry>
        <mesh
          filename="package://car2/meshes/leftwheel.STL" />
      </geometry>
      <material
        name="">
        <color
          rgba="0.64706 0.61961 0.58824 1" />
      </material>
    </visual>
    <collision>
      <origin
        xyz="0 0 0"
        rpy="0 0 0" />
      <geometry>
        <mesh
          filename="package://car2/meshes/leftwheel.STL" />
      </geometry>
    </collision>
  </link>
  <joint
    name="leftwheel_joint"
    type="continuous">
    <origin
      xyz="0.055 -0.110423702246605 -0.035"
      rpy="-1.5707963267949 -0.105014840444308 3.14159265358979" />
    <parent
      link="base_link" />
    <child
      link="leftwheel" />
    <axis
      xyz="0 0 1" />
  </joint>
  <link
    name="rightwheel">
    <inertial>
      <origin
        xyz="-1.6653E-16 4.1633E-17 -0.0098391"
        rpy="0 0 0" />
      <mass
        value="0.3096" />
      <inertia
        ixx="9.7396E-05"
        ixy="0.0"
        ixz="0.0"
        iyy="9.7396E-05"
        iyz="0.0"
        izz="0.00017415" />
    </inertial>
    <visual>
      <origin
        xyz="0 0 0"
        rpy="0 0 0" />
      <geometry>
        <mesh
          filename="package://car2/meshes/rightwheel.STL" />
      </geometry>
      <material
        name="">
        <color
          rgba="0.64706 0.61961 0.58824 1" />
      </material>
    </visual>
    <collision>
      <origin
        xyz="0 0 0"
        rpy="0 0 0" />
      <geometry>
        <mesh
          filename="package://car2/meshes/rightwheel.STL" />
      </geometry>
    </collision>
  </link>
  <joint
    name="rightwheel_joint"
    type="continuous">
    <origin
      xyz="0.055 0.110423702246602 -0.035"
      rpy="1.5707963267949 -0.261061307663736 0" />
    <parent
      link="base_link" />
    <child
      link="rightwheel" />
    <axis
      xyz="0 0 1" />
  </joint>
  <link
    name="link1">
    <inertial>
      <origin
        xyz="0.020912 -0.0016438 0.15"
        rpy="0 0 0" />
      <mass
        value="7.0138" />
      <inertia
        ixx="0.075289"
        ixy="0.00078402"
        ixz="0.0"
        iyy="0.065376"
        iyz="0.0"
        izz="0.035458" />
    </inertial>
    <visual>
      <origin
        xyz="0 0 0"
        rpy="0 0 0" />
      <geometry>
        <mesh
          filename="package://car2/meshes/link1.STL" />
      </geometry>
      <material
        name="">
        <color
          rgba="1 1 1 0.35" />
      </material>
    </visual>
    <collision>
      <origin
        xyz="0 0 0"
        rpy="0 0 0" />
      <geometry>
        <mesh
          filename="package://car2/meshes/link1.STL" />
      </geometry>
    </collision>
  </link>
  <joint
    name="joint1"
    type="revolute">
    <origin
      xyz="0 0 0.05"
      rpy="0 0 0" />
    <parent
      link="base_link" />
    <child
      link="link1" />
    <axis
      xyz="0 0 1" />
    <limit
      lower="-3.14"
      upper="3.14"
      effort="10.0"
      velocity="1.5" />
  </joint>
  <link
    name="link2">
    <inertial>
      <origin
        xyz="-0.13517 2.2454E-16 0"
        rpy="0 0 0" />
      <mass
        value="1.2926" />
      <inertia
        ixx="0.0033047"
        ixy="0.000736"
        ixz="0.0"
        iyy="0.012724"
        iyz="0.0"
        izz="0.012724" />
    </inertial>
    <visual>
      <origin
        xyz="0 0 0"
        rpy="0 0 0" />
      <geometry>
        <mesh
          filename="package://car2/meshes/link2.STL" />
      </geometry>
      <material
        name="">
        <color
          rgba="1 1 1 0.35" />
      </material>
    </visual>
    <collision>
      <origin
        xyz="0 0 0"
        rpy="0 0 0" />
      <geometry>
        <mesh
          filename="package://car2/meshes/link2.STL" />
      </geometry>
    </collision>
  </link>
  <joint
    name="joint2"
    type="prismatic">
    <origin
      xyz="0 0 0.25"
      rpy="0 0 -0.078442" />
    <parent
      link="link1" />
    <child
      link="link2" />
    <axis
      xyz="0 0 1" />
    <limit
      lower="-0.2"
      upper="0"
      effort="50.0"
      velocity="1.5" />
  </joint>
  <link
    name="link3">
    <inertial>
      <origin
        xyz="0.094255 1.3965E-16 1.6653E-16"
        rpy="0 0 0" />
      <mass
        value="2.2879" />
      <inertia
        ixx="0.0027483"
        ixy="0.00155455"
        ixz="0.0"
        iyy="0.022648"
        iyz="0.0"
        izz="0.02234" />
    </inertial>
    <visual>
      <origin
        xyz="0 0 0"
        rpy="0 0 0" />
      <geometry>
        <mesh
          filename="package://car2/meshes/link3.STL" />
      </geometry>
      <material
        name="">
        <color
          rgba="1 1 1 0.35" />
      </material>
    </visual>
    <collision>
      <origin
        xyz="0 0 0"
        rpy="0 0 0" />
      <geometry>
        <mesh
          filename="package://car2/meshes/link3.STL" />
      </geometry>
    </collision>
  </link>
  <joint
    name="joint3"
    type="prismatic">
    <origin
      xyz="-0.3 0 0"
      rpy="0 0 0" />
    <parent
      link="link2" />
    <child
      link="link3" />
    <axis
      xyz="1 0 0" />
    <limit
      lower="-0.26"
      upper="0"
      effort="10.0"
      velocity="1.5" />
  </joint>
  <link
    name="link4">
    <inertial>
      <origin
        xyz="-0.076653 5.6379E-17 0"
        rpy="0 0 0" />
      <mass
        value="2.5617" />
      <inertia
        ixx="0.0038358"
        ixy="0.0015474"
        ixz="0.0"
        iyy="0.023401"
        iyz="0.0"
        izz="0.022599" />
    </inertial>
    <visual>
      <origin
        xyz="0 0 0"
        rpy="0 0 0" />
      <geometry>
        <mesh
          filename="package://car2/meshes/link4.STL" />
      </geometry>
      <material
        name="">
        <color
          rgba="1 1 1 0.35" />
      </material>
    </visual>
    <collision>
      <origin
        xyz="0 0 0"
        rpy="0 0 0" />
      <geometry>
        <mesh
          filename="package://car2/meshes/link4.STL" />
      </geometry>
    </collision>
  </link>
  <joint
    name="joint4"
    type="revolute">
    <origin
      xyz="-0.1216 0 0"
      rpy="0 0 0" />
    <parent
      link="link3" />
    <child
      link="link4" />
    <axis
      xyz="0 -1 0" />
    <limit
      lower="-1.57"
      upper="1.57"
      effort="10.0"
      velocity="1.5" />
  </joint>
  <link
    name="link5">
    <inertial>
      <origin
        xyz="-0.023077 2.949E-17 1.1102E-16"
        rpy="0 0 0" />
      <mass
        value="1.748" />
      <inertia
        ixx="0.0084172"
        ixy="0.0002877"
        ixz="0.0"
        iyy="0.0047344"
        iyz="0.0"
        izz="0.0047344" />
    </inertial>
    <visual>
      <origin
        xyz="0 0 0"
        rpy="0 0 0" />
      <geometry>
        <mesh
          filename="package://car2/meshes/link5.STL" />
      </geometry>
      <material
        name="">
        <color
          rgba="1 1 1 0.35" />
      </material>
    </visual>
    <collision>
      <origin
        xyz="0 0 0"
        rpy="0 0 0" />
      <geometry>
        <mesh
          filename="package://car2/meshes/link5.STL" />
      </geometry>
    </collision>
  </link>
  <joint
    name="joint5"
    type="revolute">
    <origin
      xyz="-0.25745 0 0"
      rpy="0 0 0" />
    <parent
      link="link4" />
    <child
      link="link5" />
    <axis
      xyz="-1 0 0" />
    <limit
      lower="-3.14"
      upper="3.14"
      effort="0"
      velocity="1.5" />
  </joint>
  <link
    name="finger1">
    <inertial>
      <origin
        xyz="-0.043191 -0.0022229 1.6653E-16"
        rpy="0 0 0" />
      <mass
        value="0.097614" />
      <inertia
        ixx="3.3639E-05"
        ixy="1.209E-05"
        ixz="6.7E-8"
        iyy="0.0001198"
        iyz="4.6E-8"
        izz="0.00011277" />
    </inertial>
    <visual>
      <origin
        xyz="0 0 0"
        rpy="0 0 0" />
      <geometry>
        <mesh
          filename="package://car2/meshes/finger1.STL" />
      </geometry>
      <material
        name="">
        <color
          rgba="1 1 1 0.35" />
      </material>
    </visual>
    <collision>
      <origin
        xyz="0 0 0"
        rpy="0 0 0" />
      <geometry>
        <mesh
          filename="package://car2/meshes/finger1.STL" />
      </geometry>
    </collision>
  </link>
  <joint
    name="fin1"
    type="prismatic">
    <origin
      xyz="-0.05 0.076716 -0.00044365"
      rpy="-0.0057829 0 0" />
    <parent
      link="link5" />
    <child
      link="finger1" />
    <axis
      xyz="0 0.99998 0.0057829" />
    <limit
      lower="-0.05"
      upper="0"
      effort="30.0"
      velocity="1.0" />
  </joint>
  <link
    name="finger2">
    <inertial>
      <origin
        xyz="-0.043191 0.0022229 2.2204E-16"
        rpy="0 0 0" />
      <mass
        value="0.097614" />
      <inertia
        ixx="3.3639E-05"
        ixy="1.209E-05"
        ixz="6.7E-8"
        iyy="0.0001198"
        iyz="4.6E-8"
        izz="0.00011277" />
    </inertial>
    <visual>
      <origin
        xyz="0 0 0"
        rpy="0 0 0" />
      <geometry>
        <mesh
          filename="package://car2/meshes/finger2.STL" />
      </geometry>
      <material
        name="">
        <color
          rgba="1 1 1 0.35" />
      </material>
    </visual>
    <collision>
      <origin
        xyz="0 0 0"
        rpy="0 0 0" />
      <geometry>
        <mesh
          filename="package://car2/meshes/finger2.STL" />
      </geometry>
    </collision>
  </link>
  <joint
    name="fin2"
    type="prismatic">
    <origin
      xyz="-0.05 -0.077005 0.00044532"
      rpy="-0.0057829 0 0" />
    <parent
      link="link5" />
    <child
      link="finger2" />
    <axis
      xyz="0 0.99998 0.0057829" />
    <limit
      lower="0"
      upper="0.05"
      effort="30.0"
      velocity="1.0" />
  </joint>
</robot>